<?xml version="1.0" ?>
<!-- =================================================================================== -->
<!-- |    This document was autogenerated by xacro from src/quad_robot/quad_robot_description/urdf/quad_robot.xacro | -->
<!-- |    EDITING THIS FILE BY HAND IS NOT RECOMMENDED                                 | -->
<!-- =================================================================================== -->
<robot name="quad_robot">
  <material name="silver">
    <color rgba="0.700 0.700 0.700 1.000"/>
  </material>
  <material name="black">
    <color rgba="0.0 0.0 0.0 1.0"/>
  </material>
  <material name="blue">
    <color rgba="0.0 0.0 0.8 1.0"/>
  </material>
  <material name="skyblue">
    <color rgba="0.0 0.8862745098039215 0.9098039215686274 1.0"/>
  </material>
  <material name="green">
    <color rgba="0.0 0.8 0.0 1.0"/>
  </material>
  <material name="grey">
    <color rgba="0.2 0.2 0.2 1.0"/>
  </material>
  <material name="orange">
    <color rgba="1.0 0.4235294117647059 0.0392156862745098 1.0"/>
  </material>
  <material name="brown">
    <color rgba="0.8705882352941177 0.8117647058823529 0.7647058823529411 1.0"/>
  </material>
  <material name="red">
    <color rgba="0.8 0.0 0.0 1.0"/>
  </material>
  <material name="yellow">
    <color rgba="1.0 1.0 0.0 1.0"/>
  </material>
  <material name="white">
    <color rgba="1.0 1.0 1.0 1.0"/>
  </material>
  <transmission name="rf_hip_joint_tran">
    <type>transmission_interface/SimpleTransmission</type>
    <joint name="rf_hip_joint">
      <hardwareInterface>hardware_interface/EffortJointInterface</hardwareInterface>
    </joint>
    <actuator name="rf_hip_joint_actr">
      <hardwareInterface>hardware_interface/EffortJointInterface</hardwareInterface>
      <mechanicalReduction>1</mechanicalReduction>
    </actuator>
  </transmission>
  <transmission name="rh_hip_joint_tran">
    <type>transmission_interface/SimpleTransmission</type>
    <joint name="rh_hip_joint">
      <hardwareInterface>hardware_interface/EffortJointInterface</hardwareInterface>
    </joint>
    <actuator name="rh_hip_joint_actr">
      <hardwareInterface>hardware_interface/EffortJointInterface</hardwareInterface>
      <mechanicalReduction>1</mechanicalReduction>
    </actuator>
  </transmission>
  <transmission name="lf_hip_joint_tran">
    <type>transmission_interface/SimpleTransmission</type>
    <joint name="lf_hip_joint">
      <hardwareInterface>hardware_interface/EffortJointInterface</hardwareInterface>
    </joint>
    <actuator name="lf_hip_joint_actr">
      <hardwareInterface>hardware_interface/EffortJointInterface</hardwareInterface>
      <mechanicalReduction>1</mechanicalReduction>
    </actuator>
  </transmission>
  <transmission name="lh_hip_joint_tran">
    <type>transmission_interface/SimpleTransmission</type>
    <joint name="lh_hip_joint">
      <hardwareInterface>hardware_interface/EffortJointInterface</hardwareInterface>
    </joint>
    <actuator name="lh_hip_joint_actr">
      <hardwareInterface>hardware_interface/EffortJointInterface</hardwareInterface>
      <mechanicalReduction>1</mechanicalReduction>
    </actuator>
  </transmission>
  <transmission name="rf_upper_leg_joint_tran">
    <type>transmission_interface/SimpleTransmission</type>
    <joint name="rf_upper_leg_joint">
      <hardwareInterface>hardware_interface/EffortJointInterface</hardwareInterface>
    </joint>
    <actuator name="rf_upper_leg_joint_actr">
      <hardwareInterface>hardware_interface/EffortJointInterface</hardwareInterface>
      <mechanicalReduction>1</mechanicalReduction>
    </actuator>
  </transmission>
  <transmission name="rh_upper_leg_joint_tran">
    <type>transmission_interface/SimpleTransmission</type>
    <joint name="rh_upper_leg_joint">
      <hardwareInterface>hardware_interface/EffortJointInterface</hardwareInterface>
    </joint>
    <actuator name="rh_upper_leg_joint_actr">
      <hardwareInterface>hardware_interface/EffortJointInterface</hardwareInterface>
      <mechanicalReduction>1</mechanicalReduction>
    </actuator>
  </transmission>
  <transmission name="lf_upper_leg_joint_tran">
    <type>transmission_interface/SimpleTransmission</type>
    <joint name="lf_upper_leg_joint">
      <hardwareInterface>hardware_interface/EffortJointInterface</hardwareInterface>
    </joint>
    <actuator name="lf_upper_leg_joint_actr">
      <hardwareInterface>hardware_interface/EffortJointInterface</hardwareInterface>
      <mechanicalReduction>1</mechanicalReduction>
    </actuator>
  </transmission>
  <transmission name="lh_upper_leg_joint_tran">
    <type>transmission_interface/SimpleTransmission</type>
    <joint name="lh_upper_leg_joint">
      <hardwareInterface>hardware_interface/EffortJointInterface</hardwareInterface>
    </joint>
    <actuator name="lh_upper_leg_joint_actr">
      <hardwareInterface>hardware_interface/EffortJointInterface</hardwareInterface>
      <mechanicalReduction>1</mechanicalReduction>
    </actuator>
  </transmission>
  <transmission name="rf_lower_leg_joint_tran">
    <type>transmission_interface/SimpleTransmission</type>
    <joint name="rf_lower_leg_joint">
      <hardwareInterface>hardware_interface/EffortJointInterface</hardwareInterface>
    </joint>
    <actuator name="rf_lower_leg_joint_actr">
      <hardwareInterface>hardware_interface/EffortJointInterface</hardwareInterface>
      <mechanicalReduction>1</mechanicalReduction>
    </actuator>
  </transmission>
  <transmission name="rh_lower_leg_joint_tran">
    <type>transmission_interface/SimpleTransmission</type>
    <joint name="rh_lower_leg_joint">
      <hardwareInterface>hardware_interface/EffortJointInterface</hardwareInterface>
    </joint>
    <actuator name="rh_lower_leg_joint_actr">
      <hardwareInterface>hardware_interface/EffortJointInterface</hardwareInterface>
      <mechanicalReduction>1</mechanicalReduction>
    </actuator>
  </transmission>
  <transmission name="lf_lower_leg_joint_tran">
    <type>transmission_interface/SimpleTransmission</type>
    <joint name="lf_lower_leg_joint">
      <hardwareInterface>hardware_interface/EffortJointInterface</hardwareInterface>
    </joint>
    <actuator name="lf_lower_leg_joint_actr">
      <hardwareInterface>hardware_interface/EffortJointInterface</hardwareInterface>
      <mechanicalReduction>1</mechanicalReduction>
    </actuator>
  </transmission>
  <transmission name="lh_lower_leg_joint_tran">
    <type>transmission_interface/SimpleTransmission</type>
    <joint name="lh_lower_leg_joint">
      <hardwareInterface>hardware_interface/EffortJointInterface</hardwareInterface>
    </joint>
    <actuator name="lh_lower_leg_joint_actr">
      <hardwareInterface>hardware_interface/EffortJointInterface</hardwareInterface>
      <mechanicalReduction>1</mechanicalReduction>
    </actuator>
  </transmission>
  <!-- ros_control plugin -->
  <gazebo>
    <plugin filename="libgazebo_ros2_control.so" name="gazebo_ros2_control">
      <!-- <robot_sim_type>gazebo_ros2_control/GazeboSystem</robot_sim_type> -->
      <robot_param>robot_description</robot_param>
      <robot_param_node>robot_state_publisher</robot_param_node>
      <!-- <parameters>$(find quad_robot_gazebo)/config/quad_robot_position_controller.yaml</parameters> -->
      <parameters>/home/ubuntu/champ_ws/install/quad_robot_gazebo/share/quad_robot_gazebo/config/quad_robot_effort_controller.yaml</parameters>
    </plugin>
  </gazebo>

  <gazebo reference="base_link">
    <material>Gazebo/FlatBlack</material>
  </gazebo>
  <gazebo reference="rf_hip_link">
    <material>Gazebo/FlatBlack</material>
  </gazebo>
  <gazebo reference="rh_hip_link">
    <material>Gazebo/FlatBlack</material>
  </gazebo>
  <gazebo reference="lf_hip_link">
    <material>Gazebo/FlatBlack</material>
  </gazebo>
  <gazebo reference="lh_hip_link">
    <material>Gazebo/FlatBlack</material>
  </gazebo>
  <!-- ********************************************************************** -->
  <gazebo reference="rf_upper_leg_link">
    <material>Gazebo/FlatBlack</material>
  </gazebo>
  <gazebo reference="rh_upper_leg_link">
    <material>Gazebo/FlatBlack</material>
  </gazebo>
  <gazebo reference="lf_upper_leg_link">
    <material>Gazebo/FlatBlack</material>
  </gazebo>
  <gazebo reference="lh_upper_leg_link">
    <material>Gazebo/FlatBlack</material>
  </gazebo>
  <!-- ********************************************************************** -->
  <gazebo reference="rf_lower_leg_link">
    <material>Gazebo/FlatBlack</material>
    <!-- mu上げると滑る、下げると止まる -->
    <!-- kp上げると滑る -->
    <!-- kd上げると地面に練り込む -->
    <!-- mindepth 上げると沈む -->
    <kp>1e5</kp>
    <kd>100</kd>
    <mu1>0.8</mu1>
    <mu2>0.8</mu2>
    <fdir1>1 0 0</fdir1>
    <maxVel>0.1</maxVel>
    <minDepth>0.001</minDepth>
  </gazebo>
  <gazebo reference="rh_lower_leg_link">
    <material>Gazebo/FlatBlack</material>
    <kp>1e5</kp>
    <kd>100</kd>
    <mu1>0.8</mu1>
    <mu2>0.8</mu2>
    <fdir1>1 0 0</fdir1>
    <maxVel>0.1</maxVel>
    <minDepth>0.001</minDepth>
  </gazebo>
  <gazebo reference="lf_lower_leg_link">
    <material>Gazebo/FlatBlack</material>
    <kp>1e5</kp>
    <kd>100</kd>
    <mu1>0.8</mu1>
    <mu2>0.8</mu2>
    <fdir1>1 0 0</fdir1>
    <maxVel>0.1</maxVel>
    <minDepth>0.001</minDepth>
  </gazebo>
  <gazebo reference="lh_lower_leg_link">
    <material>Gazebo/FlatBlack</material>
    <kp>1e5</kp>
    <kd>100</kd>
    <mu1>0.8</mu1>
    <mu2>0.8</mu2>
    <fdir1>1 0 0</fdir1>
    <maxVel>0.1</maxVel>
    <minDepth>0.001</minDepth>
  </gazebo>
  <!-- TODO add joint tag to <dynamics damping="0.0" friction="10.0"/> -->
  <!-- TODO inertiaのoriginとか触ると、場所変わるのでNG -->
  <!-- TODO add imu_link -->

  <link name="base_link">
    <inertial>
      <origin xyz="0 0 0" rpy="0 0 0"/>
      <mass value="3.949377918410707"/>
      <inertia ixx="0.013212" iyy="0.055202" izz="0.063976" ixy="0.0" iyz="0.0" ixz="0.000785"/>
    </inertial>
    <visual>
      <origin xyz="0 0 0" rpy="0 0 0"/>
      <geometry>
        <mesh filename="file://$(find quad_robot_description)/meshes/base_link.stl" scale="0.001 0.001 0.001"/>
      </geometry>
      <material name="${main_color}"/>
    </visual>
    <!-- <collision>
      <origin xyz="0 0 0" rpy="0 0 0"/>
      <geometry>
        <mesh filename="file://$(find quad_robot_description)/meshes/base_link.stl" scale="0.001 0.001 0.001"/>
      </geometry>
    </collision> -->
  </link>

  <!-- TODO add foot link -->
  <link name="rf_foot_link"/>
  <joint name="rf_foot_joint" type="fixed">
    <parent link="rf_lower_leg_link"/>
    <child link="rf_foot_link"/>
    <origin rpy="0 0 0" xyz="0 0 -0.11"/>
  </joint>
  <link name="rh_foot_link"/>
  <joint name="rh_foot_joint" type="fixed">
    <parent link="rh_lower_leg_link"/>
    <child link="rh_foot_link"/>
    <origin rpy="0 0 0" xyz="0 0 -0.11"/>
  </joint>
  <link name="lf_foot_link"/>
  <joint name="lf_foot_joint" type="fixed">
    <parent link="lf_lower_leg_link"/>
    <child link="lf_foot_link"/>
    <origin rpy="0 0 0" xyz="0 0 -0.11"/>
  </joint>
  <link name="lh_foot_link"/>
  <joint name="lh_foot_joint" type="fixed">
    <parent link="lh_lower_leg_link"/>
    <child link="lh_foot_link"/>
    <origin rpy="0 0 0" xyz="0 0 -0.11"/>
  </joint>
  <link name="rf_hip_link">
    <inertial>
      <origin rpy="0 0 0" xyz="0.04000000000000005 -0.0033883605352012514 1.815433672304822e-17"/>
      <mass value="0.418842162082933"/>
      <inertia ixx="0.000398" ixy="0.0" ixz="-0.0" iyy="0.000427" iyz="-0.0" izz="0.000416"/>
    </inertial>
    <visual>
      <origin rpy="0 0 0" xyz="-0.05 0.06 -0.0"/>
      <geometry>
        <mesh filename="file:///home/ubuntu/champ_ws/install/quad_robot_description/share/quad_robot_description/meshes/rf_hip_link.stl" scale="0.001 0.001 0.001"/>
      </geometry>
      <material name="grey"/>
    </visual>
    <!-- <collision>
      <origin rpy="0 0 0" xyz="-0.05 0.06 -0.0"/>
      <geometry>
        <mesh filename="file:///home/ubuntu/champ_ws/install/quad_robot_description/share/quad_robot_description/meshes/rf_hip_link.stl" scale="0.001 0.001 0.001"/>
      </geometry>
    </collision> -->
  </link>
  <link name="rh_hip_link">
    <inertial>
      <origin rpy="0 0 0" xyz="-0.039999999999999966 -0.0033883605352011126 -2.885909027996524e-18"/>
      <mass value="0.418842162082933"/>
      <inertia ixx="0.000398" ixy="0.0" ixz="0.0" iyy="0.000427" iyz="0.0" izz="0.000416"/>
    </inertial>
    <visual>
      <origin rpy="0 0 0" xyz="0.05 0.06 -0.0"/>
      <geometry>
        <mesh filename="file:///home/ubuntu/champ_ws/install/quad_robot_description/share/quad_robot_description/meshes/rh_hip_link.stl" scale="0.001 0.001 0.001"/>
      </geometry>
      <material name="grey"/>
    </visual>
    <!-- <collision>
      <origin rpy="0 0 0" xyz="0.05 0.06 -0.0"/>
      <geometry>
        <mesh filename="file:///home/ubuntu/champ_ws/install/quad_robot_description/share/quad_robot_description/meshes/rh_hip_link.stl" scale="0.001 0.001 0.001"/>
      </geometry>
    </collision> -->
  </link>
  <link name="lf_hip_link">
    <inertial>
      <origin rpy="0 0 0" xyz="0.04000000000012972 0.0033883605352012652 8.881784197001253e-18"/>
      <mass value="0.41884216208293407"/>
      <inertia ixx="0.000398" ixy="0.0" ixz="0.0" iyy="0.000427" iyz="-0.0" izz="0.000416"/>
    </inertial>
    <visual>
      <origin rpy="0 0 0" xyz="-0.05 -0.06 -0.0"/>
      <geometry>
        <mesh filename="file:///home/ubuntu/champ_ws/install/quad_robot_description/share/quad_robot_description/meshes/lf_hip_link.stl" scale="0.001 0.001 0.001"/>
      </geometry>
      <material name="grey"/>
    </visual>
    <!-- <collision>
      <origin rpy="0 0 0" xyz="-0.05 -0.06 -0.0"/>
      <geometry>
        <mesh filename="file:///home/ubuntu/champ_ws/install/quad_robot_description/share/quad_robot_description/meshes/lf_hip_link.stl" scale="0.001 0.001 0.001"/>
      </geometry>
    </collision> -->
  </link>
  <link name="lh_hip_link">
    <inertial>
      <origin rpy="0 0 0" xyz="-0.04000000000000006 0.003388360535201196 9.766968170619275e-18"/>
      <mass value="0.418842162082933"/>
      <inertia ixx="0.000398" ixy="0.0" ixz="0.0" iyy="0.000427" iyz="-0.0" izz="0.000416"/>
    </inertial>
    <visual>
      <origin rpy="0 0 0" xyz="0.05 -0.06 -0.0"/>
      <geometry>
        <mesh filename="file:///home/ubuntu/champ_ws/install/quad_robot_description/share/quad_robot_description/meshes/lh_hip_link.stl" scale="0.001 0.001 0.001"/>
      </geometry>
      <material name="grey"/>
    </visual>
    <!-- <collision>
      <origin rpy="0 0 0" xyz="0.05 -0.06 -0.0"/>
      <geometry>
        <mesh filename="file:///home/ubuntu/champ_ws/install/quad_robot_description/share/quad_robot_description/meshes/lh_hip_link.stl" scale="0.001 0.001 0.001"/>
      </geometry>
    </collision> -->
  </link>
  <link name="rf_upper_leg_link">
    <inertial>
      <origin rpy="0 0 0" xyz="-8.652800698172314e-14 -0.01599999999999989 -0.038046278936919406"/>
      <mass value="0.16080574980884343"/>
      <inertia ixx="0.000206" ixy="-0.0" ixz="0.0" iyy="0.000226" iyz="0.0" izz="4.8e-05"/>
    </inertial>
    <visual>
      <origin rpy="0 0 0" xyz="-0.09 0.099 -0.0"/>
      <geometry>
        <mesh filename="file:///home/ubuntu/champ_ws/install/quad_robot_description/share/quad_robot_description/meshes/rf_upper_leg_link.stl" scale="0.001 0.001 0.001"/>
      </geometry>
      <material name="grey"/>
    </visual>
    <!-- <collision>
      <origin rpy="0 0 0" xyz="-0.09 0.099 -0.0"/>
      <geometry>
        <mesh filename="file:///home/ubuntu/champ_ws/install/quad_robot_description/share/quad_robot_description/meshes/rf_upper_leg_link.stl" scale="0.001 0.001 0.001"/>
      </geometry>
    </collision> -->
  </link>
  <link name="rh_upper_leg_link">
    <inertial>
      <origin rpy="0 0 0" xyz="-8.662515149637784e-14 -0.015999999999999626 -0.03804627893691973"/>
      <mass value="0.16080574980884343"/>
      <inertia ixx="0.000206" ixy="-0.0" ixz="0.0" iyy="0.000226" iyz="0.0" izz="4.8e-05"/>
    </inertial>
    <visual>
      <origin rpy="0 0 0" xyz="0.09 0.099 0.0"/>
      <geometry>
        <mesh filename="file:///home/ubuntu/champ_ws/install/quad_robot_description/share/quad_robot_description/meshes/rh_upper_leg_link.stl" scale="0.001 0.001 0.001"/>
      </geometry>
      <material name="grey"/>
    </visual>
    <!-- <collision>
      <origin rpy="0 0 0" xyz="0.09 0.099 0.0"/>
      <geometry>
        <mesh filename="file:///home/ubuntu/champ_ws/install/quad_robot_description/share/quad_robot_description/meshes/rh_upper_leg_link.stl" scale="0.001 0.001 0.001"/>
      </geometry>
    </collision> -->
  </link>
  <link name="lf_upper_leg_link">
    <inertial>
      <origin rpy="0 0 0" xyz="-8.66806626476091e-14 0.016000000000000167 -0.03804627893691959"/>
      <mass value="0.16080574980884343"/>
      <inertia ixx="0.000206" ixy="0.0" ixz="0.0" iyy="0.000226" iyz="0.0" izz="4.8e-05"/>
    </inertial>
    <visual>
      <origin rpy="0 0 0" xyz="-0.09 -0.099 0.0"/>
      <geometry>
        <mesh filename="file:///home/ubuntu/champ_ws/install/quad_robot_description/share/quad_robot_description/meshes/lf_upper_leg_link.stl" scale="0.001 0.001 0.001"/>
      </geometry>
      <material name="grey"/>
    </visual>
    <!-- <collision>
      <origin rpy="0 0 0" xyz="-0.09 -0.099 0.0"/>
      <geometry>
        <mesh filename="file:///home/ubuntu/champ_ws/install/quad_robot_description/share/quad_robot_description/meshes/lf_upper_leg_link.stl" scale="0.001 0.001 0.001"/>
      </geometry>
    </collision> -->
  </link>
  <link name="lh_upper_leg_link">
    <inertial>
      <origin rpy="0 0 0" xyz="-8.67778071622638e-14 0.015999999999999848 -0.038046278936919455"/>
      <mass value="0.16080574980884343"/>
      <inertia ixx="0.000206" ixy="-0.0" ixz="0.0" iyy="0.000226" iyz="0.0" izz="4.8e-05"/>
    </inertial>
    <visual>
      <origin rpy="0 0 0" xyz="0.09 -0.099 -0.0"/>
      <geometry>
        <mesh filename="file:///home/ubuntu/champ_ws/install/quad_robot_description/share/quad_robot_description/meshes/lh_upper_leg_link.stl" scale="0.001 0.001 0.001"/>
      </geometry>
      <material name="grey"/>
    </visual>
    <!-- <collision>
      <origin rpy="0 0 0" xyz="0.09 -0.099 -0.0"/>
      <geometry>
        <mesh filename="file:///home/ubuntu/champ_ws/install/quad_robot_description/share/quad_robot_description/meshes/lh_upper_leg_link.stl" scale="0.001 0.001 0.001"/>
      </geometry>
    </collision> -->
  </link>
  <link name="rf_lower_leg_link">
    <inertial>
      <origin rpy="0 0 0" xyz="1.16579398690142e-07 -0.010000000167776815 -0.04255385923514293"/>
      <mass value="0.09412944960610932"/>
      <inertia ixx="0.00014" ixy="0.0" ixz="-0.0" iyy="0.000149" iyz="0.0" izz="1.5e-05"/>
    </inertial>
    <visual>
      <origin rpy="0 0 0" xyz="-0.09 0.105 0.1"/>
      <geometry>
        <mesh filename="file:///home/ubuntu/champ_ws/install/quad_robot_description/share/quad_robot_description/meshes/rf_lower_leg_link.stl" scale="0.001 0.001 0.001"/>
      </geometry>
      <material name="grey"/>
    </visual>
    <!-- <collision>
      <origin rpy="0 0 0" xyz="-0.09 0.105 0.1"/>
      <geometry>
        <mesh filename="file:///home/ubuntu/champ_ws/install/quad_robot_description/share/quad_robot_description/meshes/rf_lower_leg_link.stl" scale="0.001 0.001 0.001"/>
      </geometry>
    </collision> -->
  </link>
  <link name="rh_lower_leg_link">
    <inertial>
      <origin rpy="0 0 0" xyz="1.1657939859299749e-07 -0.01000000016777669 -0.042553859235143515"/>
      <mass value="0.09412944960610932"/>
      <inertia ixx="0.00014" ixy="0.0" ixz="-0.0" iyy="0.000149" iyz="0.0" izz="1.5e-05"/>
    </inertial>
    <visual>
      <origin rpy="0 0 0" xyz="0.09 0.105 0.1"/>
      <geometry>
        <mesh filename="file:///home/ubuntu/champ_ws/install/quad_robot_description/share/quad_robot_description/meshes/rh_lower_leg_link.stl" scale="0.001 0.001 0.001"/>
      </geometry>
      <material name="grey"/>
    </visual>
    <!-- <collision>
      <origin rpy="0 0 0" xyz="0.09 0.105 0.1"/>
      <geometry>
        <mesh filename="file:///home/ubuntu/champ_ws/install/quad_robot_description/share/quad_robot_description/meshes/rh_lower_leg_link.stl" scale="0.001 0.001 0.001"/>
      </geometry>
    </collision> -->
  </link>
  <link name="lf_lower_leg_link">
    <inertial>
      <origin rpy="0 0 0" xyz="1.1657939852360855e-07 0.009999999832223147 -0.04255385923514313"/>
      <mass value="0.09412944960610932"/>
      <inertia ixx="0.00014" ixy="0.0" ixz="-0.0" iyy="0.000149" iyz="0.0" izz="1.5e-05"/>
    </inertial>
    <visual>
      <origin rpy="0 0 0" xyz="-0.09 -0.105 0.1"/>
      <geometry>
        <mesh filename="file:///home/ubuntu/champ_ws/install/quad_robot_description/share/quad_robot_description/meshes/lf_lower_leg_link.stl" scale="0.001 0.001 0.001"/>
      </geometry>
      <material name="grey"/>
    </visual>
    <!-- <collision>
      <origin rpy="0 0 0" xyz="-0.09 -0.105 0.1"/>
      <geometry>
        <mesh filename="file:///home/ubuntu/champ_ws/install/quad_robot_description/share/quad_robot_description/meshes/lf_lower_leg_link.stl" scale="0.001 0.001 0.001"/>
      </geometry>
    </collision> -->
  </link>
  <link name="lh_lower_leg_link">
    <inertial>
      <origin rpy="0 0 0" xyz="1.1657939841258624e-07 0.009999999832222856 -0.04255385923514293"/>
      <mass value="0.09412944960610932"/>
      <inertia ixx="0.00014" ixy="0.0" ixz="-0.0" iyy="0.000149" iyz="0.0" izz="1.5e-05"/>
    </inertial>
    <visual>
      <origin rpy="0 0 0" xyz="0.09 -0.105 0.1"/>
      <geometry>
        <mesh filename="file:///home/ubuntu/champ_ws/install/quad_robot_description/share/quad_robot_description/meshes/lh_lower_leg_link.stl" scale="0.001 0.001 0.001"/>
      </geometry>
      <material name="grey"/>
    </visual>
    <!-- <collision>
      <origin rpy="0 0 0" xyz="0.09 -0.105 0.1"/>
      <geometry>
        <mesh filename="file:///home/ubuntu/champ_ws/install/quad_robot_description/share/quad_robot_description/meshes/lh_lower_leg_link.stl" scale="0.001 0.001 0.001"/>
      </geometry>
    </collision> -->
  </link>
  <joint name="rf_hip_joint" type="revolute">
    <origin rpy="0 0 0" xyz="0.05 -0.06 0.0"/>
    <parent link="base_link"/>
    <child link="rf_hip_link"/>
    <axis xyz="-1.0 -0.0 0.0"/>
    <limit effort="100" lower="-1.570796" upper="1.570796" velocity="10"/>
    <dynamics damping="0.0" friction="10.0"/>
  </joint>
  <joint name="rh_hip_joint" type="revolute">
    <origin rpy="0 0 0" xyz="-0.05 -0.06 0.0"/>
    <parent link="base_link"/>
    <child link="rh_hip_link"/>
    <axis xyz="-1.0 0.0 0.0"/>
    <limit effort="100" lower="-1.570796" upper="1.570796" velocity="10"/>
    <dynamics damping="0.0" friction="10.0"/>
  </joint>
  <joint name="lf_hip_joint" type="revolute">
    <origin rpy="0 0 0" xyz="0.05 0.06 0.0"/>
    <parent link="base_link"/>
    <child link="lf_hip_link"/>
    <axis xyz="-1.0 0.0 0.0"/>
    <limit effort="100" lower="-1.570796" upper="1.570796" velocity="10"/>
    <dynamics damping="0.0" friction="10.0"/>
  </joint>
  <joint name="lh_hip_joint" type="revolute">
    <origin rpy="0 0 0" xyz="-0.05 0.06 0.0"/>
    <parent link="base_link"/>
    <child link="lh_hip_link"/>
    <axis xyz="-1.0 0.0 0.0"/>
    <limit effort="100" lower="-1.570796" upper="1.570796" velocity="10"/>
    <dynamics damping="0.0" friction="10.0"/>
  </joint>
  <joint name="rf_upper_leg_joint" type="revolute">
    <origin rpy="0 0 0" xyz="0.04 -0.039 0.0"/>
    <parent link="rf_hip_link"/>
    <child link="rf_upper_leg_link"/>
    <axis xyz="0.0 1.0 -0.0"/>
    <limit effort="100" lower="-1.047198" upper="1.047198" velocity="10"/>
    <dynamics damping="0.0" friction="10.0"/>
  </joint>
  <joint name="rh_upper_leg_joint" type="revolute">
    <origin rpy="0 0 0" xyz="-0.04 -0.039 -0.0"/>
    <parent link="rh_hip_link"/>
    <child link="rh_upper_leg_link"/>
    <axis xyz="0.0 1.0 0.0"/>
    <limit effort="100" lower="-1.047198" upper="1.047198" velocity="10"/>
    <dynamics damping="0.0" friction="10.0"/>
  </joint>
  <joint name="lf_upper_leg_joint" type="revolute">
    <origin rpy="0 0 0" xyz="0.04 0.039 -0.0"/>
    <parent link="lf_hip_link"/>
    <child link="lf_upper_leg_link"/>
    <axis xyz="0.0 1.0 -0.0"/>
    <limit effort="100" lower="-1.047198" upper="1.047198" velocity="10"/>
    <dynamics damping="0.0" friction="10.0"/>
  </joint>
  <joint name="lh_upper_leg_joint" type="revolute">
    <origin rpy="0 0 0" xyz="-0.04 0.039 0.0"/>
    <parent link="lh_hip_link"/>
    <child link="lh_upper_leg_link"/>
    <axis xyz="0.0 1.0 0.0"/>
    <limit effort="100" lower="-1.047198" upper="1.047198" velocity="10"/>
    <dynamics damping="0.0" friction="10.0"/>
  </joint>
  <joint name="rf_lower_leg_joint" type="revolute">
    <origin rpy="0 0 0" xyz="0.0 -0.006 -0.1"/>
    <parent link="rf_upper_leg_link"/>
    <child link="rf_lower_leg_link"/>
    <axis xyz="-0.0 1.0 -0.0"/>
    <limit effort="100" lower="-1.047198" upper="1.047198" velocity="10"/>
    <dynamics damping="0.0" friction="10.0"/>
  </joint>
  <joint name="rh_lower_leg_joint" type="revolute">
    <origin rpy="0 0 0" xyz="0.0 -0.006 -0.1"/>
    <parent link="rh_upper_leg_link"/>
    <child link="rh_lower_leg_link"/>
    <axis xyz="-0.0 1.0 0.0"/>
    <limit effort="100" lower="-1.047198" upper="1.047198" velocity="10"/>
    <dynamics damping="0.0" friction="10.0"/>
  </joint>
  <joint name="lf_lower_leg_joint" type="revolute">
    <origin rpy="0 0 0" xyz="0.0 0.006 -0.1"/>
    <parent link="lf_upper_leg_link"/>
    <child link="lf_lower_leg_link"/>
    <axis xyz="0.0 1.0 -0.0"/>
    <limit effort="100" lower="-1.047198" upper="1.047198" velocity="10"/>
    <dynamics damping="0.0" friction="10.0"/>
  </joint>
  <joint name="lh_lower_leg_joint" type="revolute">
    <origin rpy="0 0 0" xyz="0.0 0.006 -0.1"/>
    <parent link="lh_upper_leg_link"/>
    <child link="lh_lower_leg_link"/>
    <axis xyz="-0.0 1.0 0.0"/>
    <limit effort="100" lower="-1.047198" upper="1.047198" velocity="10"/>
    <dynamics damping="0.0" friction="10.0"/>
  </joint>
  <!-- Connect GazeboSystem -->
  <ros2_control name="quad_robot" type="system">
    <hardware>
      <!-- <plugin>fake_components/GenericSystem</plugin> -->
      <plugin>gazebo_ros2_control/GazeboSystem</plugin>
    </hardware>
    <joint name="rf_hip_joint">
      <command_interface name="effort">
        <!-- <param name="min">-100</param>
          <param name="max">100</param> -->
      </command_interface>
      <state_interface name="position">
        <param name="initial_value">0.0</param>
      </state_interface>
      <state_interface name="velocity"/>
    </joint>
    <joint name="rh_hip_joint">
      <command_interface name="effort">
        <!-- <param name="min">-100</param>
          <param name="max">100</param> -->
      </command_interface>
      <state_interface name="position">
        <param name="initial_value">0.0</param>
      </state_interface>
      <state_interface name="velocity"/>
    </joint>
    <joint name="lf_hip_joint">
      <command_interface name="effort">
        <!-- <param name="min">-100</param>
          <param name="max">100</param> -->
      </command_interface>
      <state_interface name="position">
        <param name="initial_value">0.0</param>
      </state_interface>
      <state_interface name="velocity"/>
    </joint>
    <joint name="lh_hip_joint">
      <command_interface name="effort">
        <!-- <param name="min">-100</param>
          <param name="max">100</param> -->
      </command_interface>
      <state_interface name="position">
        <param name="initial_value">0.0</param>
      </state_interface>
      <state_interface name="velocity"/>
    </joint>
    <!-- ********************************************************************** -->
    <joint name="rf_upper_leg_joint">
      <command_interface name="effort">
        <!-- <param name="min">-100</param>
          <param name="max">100</param> -->
      </command_interface>
      <state_interface name="position">
        <param name="initial_value">0.45</param>
      </state_interface>
      <state_interface name="velocity"/>
    </joint>
    <joint name="rh_upper_leg_joint">
      <command_interface name="effort">
        <!-- <param name="min">-100</param>
          <param name="max">100</param> -->
      </command_interface>
      <state_interface name="position">
        <param name="initial_value">0.45</param>
      </state_interface>
      <state_interface name="velocity"/>
    </joint>
    <joint name="lf_upper_leg_joint">
      <command_interface name="effort">
        <!-- <param name="min">-100</param>
          <param name="max">100</param> -->
      </command_interface>
      <state_interface name="position">
        <param name="initial_value">0.45</param>
      </state_interface>
      <state_interface name="velocity"/>
    </joint>
    <joint name="lh_upper_leg_joint">
      <command_interface name="effort">
        <!-- <param name="min">-100</param>
          <param name="max">100</param> -->
      </command_interface>
      <state_interface name="position">
        <param name="initial_value">0.45</param>
      </state_interface>
      <state_interface name="velocity"/>
    </joint>
    <!-- ********************************************************************** -->
    <joint name="rf_lower_leg_joint">
      <command_interface name="effort">
        <!-- <param name="min">-100</param>
          <param name="max">100</param> -->
      </command_interface>
      <state_interface name="position">
        <param name="initial_value">-1.047</param>
      </state_interface>
      <state_interface name="velocity"/>
    </joint>
    <joint name="rh_lower_leg_joint">
      <command_interface name="effort">
        <!-- <param name="min">-100</param>
          <param name="max">100</param> -->
      </command_interface>
      <state_interface name="position">
        <param name="initial_value">-1.047</param>
      </state_interface>
      <state_interface name="velocity"/>
    </joint>
    <joint name="lf_lower_leg_joint">
      <command_interface name="effort">
        <!-- <param name="min">-100</param>
          <param name="max">100</param> -->
      </command_interface>
      <state_interface name="position">
        <param name="initial_value">-1.047</param>
      </state_interface>
      <state_interface name="velocity"/>
    </joint>
    <joint name="lh_lower_leg_joint">
      <command_interface name="effort">
        <!-- <param name="min">-100</param>
          <param name="max">100</param> -->
      </command_interface>
      <state_interface name="position">
        <param name="initial_value">-1.047</param>
      </state_interface>
      <state_interface name="velocity"/>
    </joint>
  </ros2_control>
</robot>
